Workbook

Sheet Dashboard
A1: JNCIE-SP → Juniper SP Engineer Lab Roadmap
A3: Built for a CCIE R&S engineer: compressed fundamentals, heavy Junos behavior, services, fault isolation, and production discipline.
A5: Total Labs | B5: Completed | D5: In Progress | E5: Total Hours | G5: Completion | H5: Hours Done
A6: =COUNTA('Lab Checklist'!$A$2:$A$124) -> 123 | B6: =COUNTIF('Lab Checklist'!$L$2:$L$124,"*Completed*") -> 2 | D6: =COUNTIF('Lab Checklist'!$L$2:$L$124,"*In Progress*") -> 0 | E6: =SUM('Lab Checklist'!$H$2:$H$124) -> 488 | G6: =IFERROR(B6/A6,0) -> 0.016260163 | H6: =SUMIF('Lab Checklist'!$L$2:$L$124,"*Completed*",'Lab Checklist'!$H$2:$H$124) -> 4
A8: Phase | B8: Labs | C8: Completed | D8: Progress | F8: Recommended cadence
A9: 1. Junos Core Skills | B9: 10 | C9: =COUNTIFS('Lab Checklist'!$B$2:$B$124,A9,'Lab Checklist'!$L$2:$L$124,"*Completed*") -> 2 | D9: =IFERROR(C9/B9,0) -> 0.2 | F9: 5 days/week • 2 build labs • 1 troubleshooting rebuild • 1 review/flashcard session • 1 timed integration block Do not mark complete until you can rebuild from a blank config, explain the control plane, prove the data plane, and repair a seeded fault without a recipe.
A10: 2. IGP Engineering | B10: 12 | C10: =COUNTIFS('Lab Checklist'!$B$2:$B$124,A10,'Lab Checklist'!$L$2:$L$124,"*Completed*") -> 0 | D10: =IFERROR(C10/B10,0) -> 0
A11: 3. BGP at Scale | B11: 12 | C11: =COUNTIFS('Lab Checklist'!$B$2:$B$124,A11,'Lab Checklist'!$L$2:$L$124,"*Completed*") -> 0 | D11: =IFERROR(C11/B11,0) -> 0
A12: 4. MPLS Transport | B12: 14 | C12: =COUNTIFS('Lab Checklist'!$B$2:$B$124,A12,'Lab Checklist'!$L$2:$L$124,"*Completed*") -> 0 | D12: =IFERROR(C12/B12,0) -> 0
A13: 5. Segment Routing | B13: 8 | C13: =COUNTIFS('Lab Checklist'!$B$2:$B$124,A13,'Lab Checklist'!$L$2:$L$124,"*Completed*") -> 0 | D13: =IFERROR(C13/B13,0) -> 0
A14: 6. Layer 3 VPN | B14: 12 | C14: =COUNTIFS('Lab Checklist'!$B$2:$B$124,A14,'Lab Checklist'!$L$2:$L$124,"*Completed*") -> 0 | D14: =IFERROR(C14/B14,0) -> 0
A15: 7. Layer 2 Services | B15: 9 | C15: =COUNTIFS('Lab Checklist'!$B$2:$B$124,A15,'Lab Checklist'!$L$2:$L$124,"*Completed*") -> 0 | D15: =IFERROR(C15/B15,0) -> 0
A16: 8. EVPN | B16: 10 | C16: =COUNTIFS('Lab Checklist'!$B$2:$B$124,A16,'Lab Checklist'!$L$2:$L$124,"*Completed*") -> 0 | D16: =IFERROR(C16/B16,0) -> 0
A17: 9. Multicast | B17: 9 | C17: =COUNTIFS('Lab Checklist'!$B$2:$B$124,A17,'Lab Checklist'!$L$2:$L$124,"*Completed*") -> 0 | D17: =IFERROR(C17/B17,0) -> 0
A18: 10. CoS | B18: 7 | C18: =COUNTIFS('Lab Checklist'!$B$2:$B$124,A18,'Lab Checklist'!$L$2:$L$124,"*Completed*") -> 0 | D18: =IFERROR(C18/B18,0) -> 0
A19: 11. Operations & Automation | B19: 10 | C19: =COUNTIFS('Lab Checklist'!$B$2:$B$124,A19,'Lab Checklist'!$L$2:$L$124,"*Completed*") -> 0 | D19: =IFERROR(C19/B19,0) -> 0
A20: 12. Expert Integration | B20: 10 | C20: =COUNTIFS('Lab Checklist'!$B$2:$B$124,A20,'Lab Checklist'!$L$2:$L$124,"*Completed*") -> 0 | D20: =IFERROR(C20/B20,0) -> 0

Sheet Lab Checklist
A1: Lab ID | B1: Phase | C1: Domain | D1: Track | E1: Lab / Scenario | F1: Mastery Outcome | G1: Suggested Topology | H1: Est. Hours | I1: Difficulty | J1: Priority | K1: Dependency | L1: Status | M1: Confidence (0-5) | N1: Evidence Link / Folder | O1: Completed Date | P1: Required Evidence | Q1: Notes / Gap
A2: LAB-001 | B2: 1. Junos Core Skills | C2: Junos & Platform | D2: Foundation | E2: Safe configuration workflow | F2: Use candidate configuration, compare, commit check, confirmed commit, rollback, rescue and configuration groups safely. | G2: Minimum 4–8 routers as needed; add CE/host/traffic-generator nodes for service validation. | H2: 2 | I2: Intermediate | J2: Core | L2: ☑ Completed | M2: 0 | O2: 46243 | P2: Save configs, key show commands, packet/traffic proof, fault notes, and a short root-cause summary.
A3: LAB-002 | B3: 1. Junos Core Skills | C3: Junos & Platform | D3: Foundation | E3: Hierarchy, inheritance and groups | F3: Build reusable groups, apply-groups-except, interface-range and inspect inherited configuration. | G3: Minimum 4–8 routers as needed; add CE/host/traffic-generator nodes for service validation. | H3: 2 | I3: Intermediate | J3: Core | K3: LAB-001 | L3: ☑ Completed | M3: 0 | P3: Save configs, key show commands, packet/traffic proof, fault notes, and a short root-cause summary.
A4: LAB-003 | B4: 1. Junos Core Skills | C4: Junos & Platform | D4: Foundation | E4: Operational CLI mastery | F4: Filter, match, count, display detail/extensive, monitor, request support information and save evidence efficiently. | G4: Minimum 4–8 routers as needed; add CE/host/traffic-generator nodes for service validation. | H4: 2 | I4: Intermediate | J4: Core | K4: LAB-002 | L4: ☐ Not Started | M4: 0 | P4: Save configs, key show commands, packet/traffic proof, fault notes, and a short root-cause summary.
A5: LAB-004 | B5: 1. Junos Core Skills | C5: Junos & Platform | D5: Foundation | E5: Routing tables and next-hop resolution | F5: Trace a route across inet.0, inet.3, mpls.0 and protocol-specific tables including hidden routes. | G5: Minimum 4–8 routers as needed; add CE/host/traffic-generator nodes for service validation. | H5: 2 | I5: Intermediate | J5: Core | K5: LAB-003 | L5: ☐ Not Started | M5: 0 | P5: Save configs, key show commands, packet/traffic proof, fault notes, and a short root-cause summary.
A6: LAB-005 | B6: 1. Junos Core Skills | C6: Junos & Platform | D6: Foundation | E6: Policy language fundamentals | F6: Build deterministic term-based import/export policies using prefix lists, communities and subroutines. | G6: Minimum 4–8 routers as needed; add CE/host/traffic-generator nodes for service validation. | H6: 2 | I6: Intermediate | J6: Core | K6: LAB-004 | L6: ☐ Not Started | M6: 0 | P6: Save configs, key show commands, packet/traffic proof, fault notes, and a short root-cause summary.
A7: LAB-006 | B7: 1. Junos Core Skills | C7: Junos & Platform | D7: Foundation | E7: Policy chains and default actions | F7: Prove accept/reject behavior across chained policies and protocol defaults. | G7: Minimum 4–8 routers as needed; add CE/host/traffic-generator nodes for service validation. | H7: 2 | I7: Intermediate | J7: Core | K7: LAB-005 | L7: ☐ Not Started | M7: 0 | P7: Save configs, key show commands, packet/traffic proof, fault notes, and a short root-cause summary.
A8: LAB-007 | B8: 1. Junos Core Skills | C8: Junos & Platform | D8: Foundation | E8: RIB groups and instance import | F8: Leak selected routes between tables without accidental feedback loops. | G8: Minimum 4–8 routers as needed; add CE/host/traffic-generator nodes for service validation. | H8: 2 | I8: Intermediate | J8: Core | K8: LAB-006 | L8: ☐ Not Started | M8: 0 | P8: Save configs, key show commands, packet/traffic proof, fault notes, and a short root-cause summary.
A9: LAB-008 | B9: 1. Junos Core Skills | C9: Junos & Platform | D9: Foundation | E9: Routing instances taxonomy | F9: Demonstrate virtual-router, forwarding, vrf, vpls and evpn instance behavior. | G9: Minimum 4–8 routers as needed; add CE/host/traffic-generator nodes for service validation. | H9: 2 | I9: Intermediate | J9: Core | K9: LAB-007 | L9: ☐ Not Started | M9: 0 | P9: Save configs, key show commands, packet/traffic proof, fault notes, and a short root-cause summary.
A10: LAB-009 | B10: 1. Junos Core Skills | C10: Junos & Platform | D10: Foundation | E10: Junos automation basics | F10: Generate set-format config, use load merge/replace/override and validate repeatable deployments. | G10: Minimum 4–8 routers as needed; add CE/host/traffic-generator nodes for service validation. | H10: 2 | I10: Intermediate | J10: Core | K10: LAB-008 | L10: ☐ Not Started | M10: 0 | P10: Save configs, key show commands, packet/traffic proof, fault notes, and a short root-cause summary.
A11: LAB-010 | B11: 1. Junos Core Skills | C11: Junos & Platform | D11: Foundation | E11: Platform observability | F11: Correlate RPD, kernel, interface, PFE and chassis state during a controlled fault. | G11: Minimum 4–8 routers as needed; add CE/host/traffic-generator nodes for service validation. | H11: 2 | I11: Intermediate | J11: Core | K11: LAB-009 | L11: ☐ Not Started | M11: 0 | P11: Save configs, key show commands, packet/traffic proof, fault notes, and a short root-cause summary.
A12: LAB-011 | B12: 2. IGP Engineering | C12: OSPF & IS-IS | D12: Core | E12: OSPF multi-area baseline | F12: Build areas 0, stub, totally stub and NSSA; validate LSDB scope and route preference. | G12: Minimum 4–8 routers as needed; add CE/host/traffic-generator nodes for service validation. | H12: 3 | I12: Advanced | J12: Core | L12: ☐ Not Started | M12: 0 | P12: Save configs, key show commands, packet/traffic proof, fault notes, and a short root-cause summary.
A13: LAB-012 | B13: 2. IGP Engineering | C13: OSPF & IS-IS | D13: Core | E13: OSPF route control | F13: Control internal, external and NSSA routes with export policy, metrics and tags. | G13: Minimum 4–8 routers as needed; add CE/host/traffic-generator nodes for service validation. | H13: 3 | I13: Advanced | J13: Core | K13: LAB-011 | L13: ☐ Not Started | M13: 0 | P13: Save configs, key show commands, packet/traffic proof, fault notes, and a short root-cause summary.
A14: LAB-013 | B14: 2. IGP Engineering | C14: OSPF & IS-IS | D14: Core | E14: OSPF adjacency edge cases | F14: Troubleshoot MTU, timer, authentication, network type, area and duplicate RID failures. | G14: Minimum 4–8 routers as needed; add CE/host/traffic-generator nodes for service validation. | H14: 3 | I14: Advanced | J14: Core | K14: LAB-012 | L14: ☐ Not Started | M14: 0 | P14: Save configs, key show commands, packet/traffic proof, fault notes, and a short root-cause summary.
A15: LAB-014 | B15: 2. IGP Engineering | C15: OSPF & IS-IS | D15: Core | E15: OSPF overload and protection | F15: Test overload, prefix suppression, passive interfaces, BFD and graceful restart behavior. | G15: Minimum 4–8 routers as needed; add CE/host/traffic-generator nodes for service validation. | H15: 3 | I15: Advanced | J15: Core | K15: LAB-013 | L15: ☐ Not Started | M15: 0 | P15: Save configs, key show commands, packet/traffic proof, fault notes, and a short root-cause summary.
A16: LAB-015 | B16: 2. IGP Engineering | C16: OSPF & IS-IS | D16: Core | E16: OSPF traffic engineering database | F16: Enable TE extensions and verify link attributes used by CSPF. | G16: Minimum 4–8 routers as needed; add CE/host/traffic-generator nodes for service validation. | H16: 3 | I16: Advanced | J16: Core | K16: LAB-014 | L16: ☐ Not Started | M16: 0 | P16: Save configs, key show commands, packet/traffic proof, fault notes, and a short root-cause summary.
A17: LAB-016 | B17: 2. IGP Engineering | C17: OSPF & IS-IS | D17: Core | E17: IS-IS L1/L2 baseline | F17: Build L1, L2 and L1/L2 domains; validate attached bit, leaking and default behavior. | G17: Minimum 4–8 routers as needed; add CE/host/traffic-generator nodes for service validation. | H17: 3 | I17: Advanced | J17: Core | K17: LAB-015 | L17: ☐ Not Started | M17: 0 | P17: Save configs, key show commands, packet/traffic proof, fault notes, and a short root-cause summary.
A18: LAB-017 | B18: 2. IGP Engineering | C18: OSPF & IS-IS | D18: Core | E18: IS-IS wide metrics and topology | F18: Use wide metrics, passive, point-to-point, reference bandwidth and multi-topology concepts. | G18: Minimum 4–8 routers as needed; add CE/host/traffic-generator nodes for service validation. | H18: 3 | I18: Advanced | J18: Core | K18: LAB-016 | L18: ☐ Not Started | M18: 0 | P18: Save configs, key show commands, packet/traffic proof, fault notes, and a short root-cause summary.
A19: LAB-018 | B19: 2. IGP Engineering | C19: OSPF & IS-IS | D19: Core | E19: IS-IS route leaking and policies | F19: Leak selected L2 routes to L1 and prevent suboptimal routing or loops. | G19: Minimum 4–8 routers as needed; add CE/host/traffic-generator nodes for service validation. | H19: 3 | I19: Advanced | J19: Core | K19: LAB-017 | L19: ☐ Not Started | M19: 0 | P19: Save configs, key show commands, packet/traffic proof, fault notes, and a short root-cause summary.
A20: LAB-019 | B20: 2. IGP Engineering | C20: OSPF & IS-IS | D20: Core | E20: IS-IS adjacency edge cases | F20: Troubleshoot ISO family, NET, level, MTU, authentication and interface-mode failures. | G20: Minimum 4–8 routers as needed; add CE/host/traffic-generator nodes for service validation. | H20: 3 | I20: Advanced | J20: Core | K20: LAB-018 | L20: ☐ Not Started | M20: 0 | P20: Save configs, key show commands, packet/traffic proof, fault notes, and a short root-cause summary.
A21: LAB-020 | B21: 2. IGP Engineering | C21: OSPF & IS-IS | D21: Core | E21: IS-IS overload and protection | F21: Test overload bit, prefix export, BFD, graceful restart and adjacency holddown. | G21: Minimum 4–8 routers as needed; add CE/host/traffic-generator nodes for service validation. | H21: 3 | I21: Advanced | J21: Core | K21: LAB-019 | L21: ☐ Not Started | M21: 0 | P21: Save configs, key show commands, packet/traffic proof, fault notes, and a short root-cause summary.
A22: LAB-021 | B22: 2. IGP Engineering | C22: OSPF & IS-IS | D22: Core | E22: IGP migration OSPF to IS-IS | F22: Migrate a live core with controlled preference and no service outage. | G22: Minimum 4–8 routers as needed; add CE/host/traffic-generator nodes for service validation. | H22: 3 | I22: Advanced | J22: Core | K22: LAB-020 | L22: ☐ Not Started | M22: 0 | P22: Save configs, key show commands, packet/traffic proof, fault notes, and a short root-cause summary.
A23: LAB-022 | B23: 2. IGP Engineering | C23: OSPF & IS-IS | D23: Core | E23: IGP convergence benchmark | F23: Measure failure detection, SPF, RIB and forwarding convergence under link/node faults. | G23: Minimum 4–8 routers as needed; add CE/host/traffic-generator nodes for service validation. | H23: 3 | I23: Advanced | J23: Core | K23: LAB-021 | L23: ☐ Not Started | M23: 0 | P23: Save configs, key show commands, packet/traffic proof, fault notes, and a short root-cause summary.
A24: LAB-023 | B24: 3. BGP at Scale | C24: BGP | D24: Core | E24: eBGP and iBGP policy baseline | F24: Build explicit import/export policy and prove Junos BGP default advertisement behavior. | G24: Minimum 4–8 routers as needed; add CE/host/traffic-generator nodes for service validation. | H24: 3 | I24: Advanced | J24: Core | L24: ☐ Not Started | M24: 0 | P24: Save configs, key show commands, packet/traffic proof, fault notes, and a short root-cause summary.
A25: LAB-024 | B25: 3. BGP at Scale | C25: BGP | D25: Core | E25: BGP path selection laboratory | F25: Manipulate local preference, AS path, origin, MED, IGP cost and router ID one variable at a time. | G25: Minimum 4–8 routers as needed; add CE/host/traffic-generator nodes for service validation. | H25: 3 | I25: Advanced | J25: Core | K25: LAB-023 | L25: ☐ Not Started | M25: 0 | P25: Save configs, key show commands, packet/traffic proof, fault notes, and a short root-cause summary.
A26: LAB-025 | B26: 3. BGP at Scale | C26: BGP | D26: Core | E26: Route reflection design | F26: Deploy redundant route reflectors, clusters and clients; prove loop prevention attributes. | G26: Minimum 4–8 routers as needed; add CE/host/traffic-generator nodes for service validation. | H26: 3 | I26: Advanced | J26: Core | K26: LAB-024 | L26: ☐ Not Started | M26: 0 | P26: Save configs, key show commands, packet/traffic proof, fault notes, and a short root-cause summary.
A27: LAB-026 | B27: 3. BGP at Scale | C27: BGP | D27: Core | E27: BGP communities toolkit | F27: Use standard, large, extended and well-known communities for scalable policy. | G27: Minimum 4–8 routers as needed; add CE/host/traffic-generator nodes for service validation. | H27: 3 | I27: Advanced | J27: Core | K27: LAB-025 | L27: ☐ Not Started | M27: 0 | P27: Save configs, key show commands, packet/traffic proof, fault notes, and a short root-cause summary.
A28: LAB-027 | B28: 3. BGP at Scale | C28: BGP | D28: Core | E28: BGP route damping and flap analysis | F28: Observe flap history and evaluate when damping is operationally harmful. | G28: Minimum 4–8 routers as needed; add CE/host/traffic-generator nodes for service validation. | H28: 3 | I28: Advanced | J28: Core | K28: LAB-026 | L28: ☐ Not Started | M28: 0 | P28: Save configs, key show commands, packet/traffic proof, fault notes, and a short root-cause summary.
A29: LAB-028 | B29: 3. BGP at Scale | C29: BGP | D29: Core | E29: BGP multipath and add-path | F29: Compare equal-cost multipath, multiple-as and add-path visibility. | G29: Minimum 4–8 routers as needed; add CE/host/traffic-generator nodes for service validation. | H29: 3 | I29: Advanced | J29: Core | K29: LAB-027 | L29: ☐ Not Started | M29: 0 | P29: Save configs, key show commands, packet/traffic proof, fault notes, and a short root-cause summary.
A30: LAB-029 | B30: 3. BGP at Scale | C30: BGP | D30: Core | E30: BGP graceful restart and NSR | F30: Test control-plane restart behavior and identify stale route risks. | G30: Minimum 4–8 routers as needed; add CE/host/traffic-generator nodes for service validation. | H30: 3 | I30: Advanced | J30: Core | K30: LAB-028 | L30: ☐ Not Started | M30: 0 | P30: Save configs, key show commands, packet/traffic proof, fault notes, and a short root-cause summary.
A31: LAB-030 | B31: 3. BGP at Scale | C31: BGP | D31: Core | E31: BGP authentication and TTL security | F31: Secure sessions and troubleshoot MD5, TTL and source-address mismatch. | G31: Minimum 4–8 routers as needed; add CE/host/traffic-generator nodes for service validation. | H31: 3 | I31: Advanced | J31: Core | K31: LAB-029 | L31: ☐ Not Started | M31: 0 | P31: Save configs, key show commands, packet/traffic proof, fault notes, and a short root-cause summary.
A32: LAB-031 | B32: 3. BGP at Scale | C32: BGP | D32: Core | E32: BGP prefix-limit safety | F32: Apply warning, teardown and idle-timeout behavior without causing collateral outages. | G32: Minimum 4–8 routers as needed; add CE/host/traffic-generator nodes for service validation. | H32: 3 | I32: Advanced | J32: Core | K32: LAB-030 | L32: ☐ Not Started | M32: 0 | P32: Save configs, key show commands, packet/traffic proof, fault notes, and a short root-cause summary.
A33: LAB-032 | B33: 3. BGP at Scale | C33: BGP | D33: Core | E33: BGP labeled unicast | F33: Carry labeled IPv4 prefixes and inspect label allocation, resolution and forwarding. | G33: Minimum 4–8 routers as needed; add CE/host/traffic-generator nodes for service validation. | H33: 3 | I33: Advanced | J33: Core | K33: LAB-031 | L33: ☐ Not Started | M33: 0 | P33: Save configs, key show commands, packet/traffic proof, fault notes, and a short root-cause summary.
A34: LAB-033 | B34: 3. BGP at Scale | C34: BGP | D34: Core | E34: BGP confederation scenario | F34: Build and troubleshoot a confederation and compare it with route reflection. | G34: Minimum 4–8 routers as needed; add CE/host/traffic-generator nodes for service validation. | H34: 3 | I34: Advanced | J34: Core | K34: LAB-032 | L34: ☐ Not Started | M34: 0 | P34: Save configs, key show commands, packet/traffic proof, fault notes, and a short root-cause summary.
A35: LAB-034 | B35: 3. BGP at Scale | C35: BGP | D35: Core | E35: Internet edge policy capstone | F35: Implement customer, peer and transit policies with bogon filtering, RPKI-informed design and max-prefix controls. | G35: Minimum 4–8 routers as needed; add CE/host/traffic-generator nodes for service validation. | H35: 3 | I35: Advanced | J35: Core | K35: LAB-033 | L35: ☐ Not Started | M35: 0 | P35: Save configs, key show commands, packet/traffic proof, fault notes, and a short root-cause summary.
A36: LAB-035 | B36: 4. MPLS Transport | C36: MPLS, LDP & RSVP | D36: Expert | E36: MPLS forwarding baseline | F36: Enable MPLS and trace label push, swap, PHP and explicit-null through mpls.0. | G36: Minimum 4–8 routers as needed; add CE/host/traffic-generator nodes for service validation. | H36: 4 | I36: Expert | J36: Core | L36: ☐ Not Started | M36: 0 | P36: Save configs, key show commands, packet/traffic proof, fault notes, and a short root-cause summary.
A37: LAB-036 | B37: 4. MPLS Transport | C37: MPLS, LDP & RSVP | D37: Expert | E37: LDP transport LSP | F37: Build LDP over the IGP and verify FEC-label bindings and inet.3 resolution. | G37: Minimum 4–8 routers as needed; add CE/host/traffic-generator nodes for service validation. | H37: 4 | I37: Expert | J37: Core | K37: LAB-035 | L37: ☐ Not Started | M37: 0 | P37: Save configs, key show commands, packet/traffic proof, fault notes, and a short root-cause summary.
A38: LAB-037 | B38: 4. MPLS Transport | C38: MPLS, LDP & RSVP | D38: Expert | E38: LDP synchronization | F38: Create a link-up race and prove IGP-LDP synchronization prevents blackholing. | G38: Minimum 4–8 routers as needed; add CE/host/traffic-generator nodes for service validation. | H38: 4 | I38: Expert | J38: Core | K38: LAB-036 | L38: ☐ Not Started | M38: 0 | P38: Save configs, key show commands, packet/traffic proof, fault notes, and a short root-cause summary.
A39: LAB-038 | B39: 4. MPLS Transport | C39: MPLS, LDP & RSVP | D39: Expert | E39: LDP targeted sessions | F39: Build targeted LDP and troubleshoot transport-address reachability. | G39: Minimum 4–8 routers as needed; add CE/host/traffic-generator nodes for service validation. | H39: 4 | I39: Expert | J39: Core | K39: LAB-037 | L39: ☐ Not Started | M39: 0 | P39: Save configs, key show commands, packet/traffic proof, fault notes, and a short root-cause summary.
A40: LAB-039 | B40: 4. MPLS Transport | C40: MPLS, LDP & RSVP | D40: Expert | E40: RSVP-TE dynamic LSP | F40: Build a CSPF-signaled LSP and interpret ERO, RRO, session and path state. | G40: Minimum 4–8 routers as needed; add CE/host/traffic-generator nodes for service validation. | H40: 4 | I40: Expert | J40: Core | K40: LAB-038 | L40: ☐ Not Started | M40: 0 | P40: Save configs, key show commands, packet/traffic proof, fault notes, and a short root-cause summary.
...

Sheet Roadmap
A1: Technology-Based Progression
A3: Phase | B3: Primary Goal | C3: Exit Gate | D3: Labs | E3: Est. Hours | F3: Suggested Weeks | G3: Why It Matters
A4: 1. Junos Core Skills | B4: Junos & Platform | C4: Rebuild representative Junos & Platform services from blank config and repair at least 3 seeded faults. | D4: 10 | E4: 20 | F4: 3 | G4: Develop expert implementation and troubleshooting depth.
A5: 2. IGP Engineering | B5: OSPF & IS-IS | C5: Rebuild representative OSPF & IS-IS services from blank config and repair at least 3 seeded faults. | D5: 12 | E5: 36 | F5: 5 | G5: Develop expert implementation and troubleshooting depth.
A6: 3. BGP at Scale | B6: BGP | C6: Rebuild representative BGP services from blank config and repair at least 3 seeded faults. | D6: 12 | E6: 36 | F6: 5 | G6: Develop expert implementation and troubleshooting depth.
A7: 4. MPLS Transport | B7: MPLS, LDP & RSVP | C7: Rebuild representative MPLS, LDP & RSVP services from blank config and repair at least 3 seeded faults. | D7: 14 | E7: 56 | F7: 7 | G7: Develop expert implementation and troubleshooting depth.
A8: 5. Segment Routing | B8: SR-MPLS | C8: Rebuild representative SR-MPLS services from blank config and repair at least 3 seeded faults. | D8: 8 | E8: 32 | F8: 4 | G8: Build modern relevance beyond the classic blueprint.
A9: 6. Layer 3 VPN | B9: L3VPN | C9: Rebuild representative L3VPN services from blank config and repair at least 3 seeded faults. | D9: 12 | E9: 48 | F9: 6 | G9: Develop expert implementation and troubleshooting depth.
A10: 7. Layer 2 Services | B10: L2VPN & VPLS | C10: Rebuild representative L2VPN & VPLS services from blank config and repair at least 3 seeded faults. | D10: 9 | E10: 36 | F10: 5 | G10: Develop expert implementation and troubleshooting depth.
A11: 8. EVPN | B11: EVPN | C11: Rebuild representative EVPN services from blank config and repair at least 3 seeded faults. | D11: 10 | E11: 40 | F11: 5 | G11: Build modern relevance beyond the classic blueprint.
A12: 9. Multicast | B12: Multicast & MVPN | C12: Rebuild representative Multicast & MVPN services from blank config and repair at least 3 seeded faults. | D12: 9 | E12: 36 | F12: 5 | G12: Develop expert implementation and troubleshooting depth.
A13: 10. CoS | B13: Class of Service | C13: Rebuild representative Class of Service services from blank config and repair at least 3 seeded faults. | D13: 7 | E13: 28 | F13: 4 | G13: Develop expert implementation and troubleshooting depth.
A14: 11. Operations & Automation | B14: Operations | C14: Rebuild representative Operations services from blank config and repair at least 3 seeded faults. | D14: 10 | E14: 40 | F14: 5 | G14: Turn configuration skill into safe operations.
A15: 12. Expert Integration | B15: Integrated Troubleshooting | C15: Complete two 8-hour mocks ≥80% and pass blind troubleshooting review. | D15: 10 | E15: 80 | F15: 10 | G15: Develop expert implementation and troubleshooting depth.

Sheet Capstones
A1: Capstone & Timed Practice Scorecard
A3: Attempt | B3: Scenario | C3: Date | D3: Build % | E3: Troubleshoot % | F3: Verification % | G3: Time Mgmt % | H3: Overall %
A4: 1 | B4: IGP + MPLS core | D4: 0 | E4: 0 | F4: 0 | G4: 0 | H4: =AVERAGE(D4:G4) -> 0
A5: 2 | B5: BGP + L3VPN | D5: 0 | E5: 0 | F5: 0 | G5: 0 | H5: =AVERAGE(D5:G5) -> 0
A6: 3 | B6: L2VPN + EVPN | D6: 0 | E6: 0 | F6: 0 | G6: 0 | H6: =AVERAGE(D6:G6) -> 0
A7: 4 | B7: Multicast + CoS | D7: 0 | E7: 0 | F7: 0 | G7: 0 | H7: =AVERAGE(D7:G7) -> 0
A8: 5 | B8: 8-hour Mock Exam 1 | D8: 0 | E8: 0 | F8: 0 | G8: 0 | H8: =AVERAGE(D8:G8) -> 0
A9: 6 | B9: 8-hour Mock Exam 2 | D9: 0 | E9: 0 | F9: 0 | G9: 0 | H9: =AVERAGE(D9:G9) -> 0
A10: 7 | B10: Blind Troubleshooting 1 | D10: 0 | E10: 0 | F10: 0 | G10: 0 | H10: =AVERAGE(D10:G10) -> 0
A11: 8 | B11: Blind Troubleshooting 2 | D11: 0 | E11: 0 | F11: 0 | G11: 0 | H11: =AVERAGE(D11:G11) -> 0
A14: Pass gate: ≥80% overall, no critical reachability/isolation defect, and every change backed by pre-check, verification, and rollback.

Sheet Practice Log
A1: Date | B1: Lab ID | C1: Minutes | D1: Mode | E1: Result | F1: Fault / Gap Found | G1: Root Cause | H1: Next Action | I1: Evidence Link | J1: Revisit Date
D2: Build
D3: Build
D4: Build
D5: Build
D6: Build
D7: Build
D8: Build
D9: Build
D10: Build
D11: Build
D12: Build
D13: Build
... D201: Build

Sheet Guide
A1: How to Use This Workbook
A3: Step | B3: Action | C3: Standard
A4: 1 | B4: Select | C4: Start with Lab Checklist filtered to Priority = Core and Status = Not Started.
A5: 2 | B5: Build | C5: Configure from a blank or minimal baseline. Do not paste a full solution.
A6: 3 | B6: Explain | C6: For each protocol, explain adjacency/session formation, route/label learning, best-path choice and forwarding.
A7: 4 | B7: Prove | C7: Validate both control plane and data plane. A route in a table is not enough.
A8: 5 | B8: Break | C8: Seed at least one fault after the clean build. Record hypothesis before changing configuration.
A9: 6 | B9: Recover | C9: Apply the smallest safe change, verify service restoration and document rollback.
A10: 7 | B10: Record | C10: Attach configs, command output, packet/traffic result and root-cause note in Evidence Link / Folder.
A11: 8 | B11: Complete | C11: Mark ☑ only when confidence is ≥4 and you can repeat the lab without a recipe.
A12: 9 | B12: Revisit | C12: Use ↻ when knowledge decays or a mock exam exposes a gap.
A13: 10 | B13: Integrate | C13: After each major phase, perform a mixed fault lab before moving on.
A15: Definition of Mastery
A17: Dimension | B17: Completion Gate
A18: Control plane | B18: Can predict and verify protocol state, advertisements, policy effects and failure behavior.
A19: Data plane | B19: Can trace packet/label forwarding end to end and reconcile it with control-plane state.
A20: Troubleshooting | B20: Uses hypothesis → evidence → minimal change → verification; does not “shotgun” configuration.
A21: Operations | B21: Captures prechecks, blast radius, rollback, postchecks and evidence.
A22: Repeatability | B22: Can rebuild from blank config and automate or template repetitive elements.
A23: Communication | B23: Can explain the design and root cause clearly to another senior engineer.
A25: Official references: https://www.juniper.net/us/en/training/certification/tracks/service-provider-routing-switching/jncie-sp.html | https://learningportal.juniper.net/juniper/user_activity_info.aspx?id=EDU-JUN-JOL-JNCIE-SP | https://www.juniper.net/documentation/us/en/software/junos/mpls/mpls.pdf

Sheet Lists
A1: Status | B1: Confidence | C1: Difficulty | D1: Priority
A2: ☐ Not Started | B2: 0 | C2: Intermediate | D2: Core
A3: ◐ In Progress | B3: 1 | C3: Advanced | D3: Beyond Exam
A4: ☑ Completed | B4: 2 | C4: Expert
A5: ↻ Revisit | B5: 3
B6: 4
B7: 5
