Workbook

Sheet Guide
A1: CCIE-SP Cisco SP Engineer Lab Roadmap
A2: Technology-first roadmap for a CCIE R&S holder: exam readiness + production engineering mastery | B2: Technology-first roadmap for a CCIE R&S holder: exam readiness + production engineering mastery | C2: Technology-first roadmap for a CCIE R&S holder: exam readiness + production engineering mastery | D2: Technology-first roadmap for a CCIE R&S holder: exam readiness + production engineering mastery | E2: Technology-first roadmap for a CCIE R&S holder: exam readiness + production engineering mastery | F2: Technology-first roadmap for a CCIE R&S holder: exam readiness + production engineering mastery | G2: Technology-first roadmap for a CCIE R&S holder: exam readiness + production engineering mastery | H2: Technology-first roadmap for a CCIE R&S holder: exam readiness + production engineering mastery
A4: How to use this workbook
A5: 1 | B5: Work phase-by-phase, but revisit earlier technologies inside integrated labs.
A6: 2 | B6: Start each lab from a blank or minimal baseline; do not paste a finished solution.
A7: 3 | B7: Prove both control plane and forwarding/data plane with saved evidence.
A8: 4 | B8: Inject at least one fault for every lab marked Priority = Core or Critical.
A9: 5 | B9: Troubleshoot using hypothesis → evidence → minimal change → verification.
A10: 6 | B10: Record precheck, postcheck, rollback, and a concise root-cause note.
A11: 7 | B11: Mark Mastered only when Confidence is 4 or 5 and the Required Evidence exists.
A13: Status | B13: Meaning | C13: Confidence | D13: Mastery gate
A14: Not Started | B14: No meaningful attempt yet | C14: 0–1 | D14: Not mastered
A15: In Progress | B15: Configuration or validation is incomplete | C15: 2–3 | D15: Not mastered
A16: Blocked | B16: Lab cannot proceed; record the blocker | C16: Any | D16: Not mastered
A17: Review | B17: Works, but explanation/evidence is incomplete | C17: 3 | D17: Not mastered
A18: Mastered | B18: Repeatable without solution guide | C18: 4–5 | D18: Required evidence present
A19: Revisit | B19: Previously mastered but skill has decayed | C19: 2–3 | D19: Repeat until ≥4
A21: Mastery evidence standard
A22: Configuration | B22: Final running config or intended diff
A23: Control plane | B23: Relevant protocol/database/RIB outputs
A24: Data plane | B24: CEF/MPLS forwarding plus ping/traffic/packet proof
A25: Failure | B25: Fault injected, symptoms captured, and root cause stated
A26: Change safety | B26: Precheck, postcheck, rollback command/plan
A27: Explanation | B27: Why the behavior occurred—not only which command fixed it
A28: Timing | B28: For capstones: elapsed time and unresolved gaps

Sheet Dashboard
A1: Progress Dashboard
A2: Live formulas update when Status, Confidence, and evidence fields change | B2: Live formulas update when Status, Confidence, and evidence fields change | C2: Live formulas update when Status, Confidence, and evidence fields change | D2: Live formulas update when Status, Confidence, and evidence fields change | E2: Live formulas update when Status, Confidence, and evidence fields change | F2: Live formulas update when Status, Confidence, and evidence fields change | G2: Live formulas update when Status, Confidence, and evidence fields change | H2: Live formulas update when Status, Confidence, and evidence fields change
A4: Metric | B4: Value | D4: Phase | E4: Labs | F4: Mastered | G4: Hours | H4: Completion
A5: Total Labs | B5: =COUNTA('Lab Checklist'!$A$5:$A$165) -> 161 | D5: 1. IOS XR & SP Foundations | E5: 7 | F5: =COUNTIFS('Lab Checklist'!$B$5:$B$165,1,'Lab Checklist'!$K$5:$K$165,"Mastered") -> 0 | G5: =SUMIF('Lab Checklist'!$B$5:$B$165,1,'Lab Checklist'!$G$5:$G$165) -> 18 | H5: =IF(E5=0,0,F5/E5) -> 0
A6: Mastered | B6: =COUNTIF('Lab Checklist'!$K$5:$K$165,"Mastered") -> 0 | D6: 2. Dual-Stack IGP Engineering | E6: 12 | F6: =COUNTIFS('Lab Checklist'!$B$5:$B$165,2,'Lab Checklist'!$K$5:$K$165,"Mastered") -> 0 | G6: =SUMIF('Lab Checklist'!$B$5:$B$165,2,'Lab Checklist'!$G$5:$G$165) -> 33 | H6: =IF(E6=0,0,F6/E6) -> 0
A7: In Progress | B7: =COUNTIF('Lab Checklist'!$K$5:$K$165,"In Progress") -> 0 | D7: 3. BGP at Service-Provider Scale | E7: 14 | F7: =COUNTIFS('Lab Checklist'!$B$5:$B$165,3,'Lab Checklist'!$K$5:$K$165,"Mastered") -> 0 | G7: =SUMIF('Lab Checklist'!$B$5:$B$165,3,'Lab Checklist'!$G$5:$G$165) -> 62 | H7: =IF(E7=0,0,F7/E7) -> 0
A8: Total Estimated Hours | B8: =SUM('Lab Checklist'!$G$5:$G$165) -> 699 | D8: 4. MPLS Transport: LDP & RSVP-TE | E8: 10 | F8: =COUNTIFS('Lab Checklist'!$B$5:$B$165,4,'Lab Checklist'!$K$5:$K$165,"Mastered") -> 0 | G8: =SUMIF('Lab Checklist'!$B$5:$B$165,4,'Lab Checklist'!$G$5:$G$165) -> 44 | H8: =IF(E8=0,0,F8/E8) -> 0
A9: Completion | B9: =IF(B5=0,0,B6/B5) -> 0 | D9: 5. Segment Routing MPLS & SR-TE | E9: 13 | F9: =COUNTIFS('Lab Checklist'!$B$5:$B$165,5,'Lab Checklist'!$K$5:$K$165,"Mastered") -> 0 | G9: =SUMIF('Lab Checklist'!$B$5:$B$165,5,'Lab Checklist'!$G$5:$G$165) -> 58 | H9: =IF(E9=0,0,F9/E9) -> 0
D10: 6. L3VPN & Inter-AS | E10: 15 | F10: =COUNTIFS('Lab Checklist'!$B$5:$B$165,6,'Lab Checklist'!$K$5:$K$165,"Mastered") -> 0 | G10: =SUMIF('Lab Checklist'!$B$5:$B$165,6,'Lab Checklist'!$G$5:$G$165) -> 66 | H10: =IF(E10=0,0,F10/E10) -> 0
D11: 7. L2VPN, EVPN & Multihoming | E11: 16 | F11: =COUNTIFS('Lab Checklist'!$B$5:$B$165,7,'Lab Checklist'!$K$5:$K$165,"Mastered") -> 0 | G11: =SUMIF('Lab Checklist'!$B$5:$B$165,7,'Lab Checklist'!$G$5:$G$165) -> 72 | H11: =IF(E11=0,0,F11/E11) -> 0
A12: Mastery quality gate | B12: Value | D12: 8. Multicast & mVPN | E12: 11 | F12: =COUNTIFS('Lab Checklist'!$B$5:$B$165,8,'Lab Checklist'!$K$5:$K$165,"Mastered") -> 0 | G12: =SUMIF('Lab Checklist'!$B$5:$B$165,8,'Lab Checklist'!$G$5:$G$165) -> 48 | H12: =IF(E12=0,0,F12/E12) -> 0
A13: Confidence ≥4 | B13: Enter 4 or 5 | D13: 9. Access, Metro & Subscriber Edge | E13: 7 | F13: =COUNTIFS('Lab Checklist'!$B$5:$B$165,9,'Lab Checklist'!$K$5:$K$165,"Mastered") -> 0 | G13: =SUMIF('Lab Checklist'!$B$5:$B$165,9,'Lab Checklist'!$G$5:$G$165) -> 30 | H13: =IF(E13=0,0,F13/E13) -> 0
A14: Status | B14: Mastered | D14: 10. QoS & Traffic Engineering | E14: 8 | F14: =COUNTIFS('Lab Checklist'!$B$5:$B$165,10,'Lab Checklist'!$K$5:$K$165,"Mastered") -> 0 | G14: =SUMIF('Lab Checklist'!$B$5:$B$165,10,'Lab Checklist'!$G$5:$G$165) -> 36 | H14: =IF(E14=0,0,F14/E14) -> 0
A15: Evidence | B15: Required | D15: 11. High Availability & Fast Convergence | E15: 8 | F15: =COUNTIFS('Lab Checklist'!$B$5:$B$165,11,'Lab Checklist'!$K$5:$K$165,"Mastered") -> 0 | G15: =SUMIF('Lab Checklist'!$B$5:$B$165,11,'Lab Checklist'!$G$5:$G$165) -> 36 | H15: =IF(E15=0,0,F15/E15) -> 0
A16: Rule | B16: A lab counts as mastered only when all evidence exists; Dashboard uses Status as the progress signal. | D16: 12. Security & Infrastructure Protection | E16: 8 | F16: =COUNTIFS('Lab Checklist'!$B$5:$B$165,12,'Lab Checklist'!$K$5:$K$165,"Mastered") -> 0 | G16: =SUMIF('Lab Checklist'!$B$5:$B$165,12,'Lab Checklist'!$G$5:$G$165) -> 36 | H16: =IF(E16=0,0,F16/E16) -> 0
D17: 13. Operations, Assurance & Telemetry | E17: 10 | F17: =COUNTIFS('Lab Checklist'!$B$5:$B$165,13,'Lab Checklist'!$K$5:$K$165,"Mastered") -> 0 | G17: =SUMIF('Lab Checklist'!$B$5:$B$165,13,'Lab Checklist'!$G$5:$G$165) -> 44 | H17: =IF(E17=0,0,F17/E17) -> 0
D18: 14. Automation & Programmability | E18: 10 | F18: =COUNTIFS('Lab Checklist'!$B$5:$B$165,14,'Lab Checklist'!$K$5:$K$165,"Mastered") -> 0 | G18: =SUMIF('Lab Checklist'!$B$5:$B$165,14,'Lab Checklist'!$G$5:$G$165) -> 44 | H18: =IF(E18=0,0,F18/E18) -> 0
D19: 15. Design, Migration & Expert Integration | E19: 12 | F19: =COUNTIFS('Lab Checklist'!$B$5:$B$165,15,'Lab Checklist'!$K$5:$K$165,"Mastered") -> 0 | G19: =SUMIF('Lab Checklist'!$B$5:$B$165,15,'Lab Checklist'!$G$5:$G$165) -> 72 | H19: =IF(E19=0,0,F19/E19) -> 0

Sheet Roadmap
A1: Technology Roadmap
A2: Exit gates emphasize production behavior and repeatable troubleshooting—not topic recognition | B2: Exit gates emphasize production behavior and repeatable troubleshooting—not topic recognition | C2: Exit gates emphasize production behavior and repeatable troubleshooting—not topic recognition | D2: Exit gates emphasize production behavior and repeatable troubleshooting—not topic recognition | E2: Exit gates emphasize production behavior and repeatable troubleshooting—not topic recognition | F2: Exit gates emphasize production behavior and repeatable troubleshooting—not topic recognition | G2: Exit gates emphasize production behavior and repeatable troubleshooting—not topic recognition | H2: Exit gates emphasize production behavior and repeatable troubleshooting—not topic recognition
A4: Phase | B4: Primary Goal | C4: Exit Gate | D4: Labs | E4: Est. Hours | F4: Suggested Weeks | G4: Why It Matters
A5: 1. IOS XR & SP Foundations | B5: Operate IOS XR safely and build repeatable lab baselines | C5: Commit/rollback, interface/bundle, RIB/FIB and evidence workflow are fluent | D5: 7 | E5: 18 | F5: 2–3 | G5: Transfers your CCIE R&S base into IOS XR and SP-scale underlays.
A6: 2. Dual-Stack IGP Engineering | B6: Engineer scalable IS-IS and OSPFv2/v3 underlays | C6: Predict adjacencies, LSDB/SPF behavior, metrics, summarization and convergence | D6: 12 | E6: 33 | F6: 4–5 | G6: Transfers your CCIE R&S base into IOS XR and SP-scale underlays.
A7: 3. BGP at Service-Provider Scale | B7: Build policy-rich, scalable interdomain routing | C7: Explain and prove best path, RR behavior, policy, PIC and graceful operations | D7: 14 | E7: 62 | F7: 5–6 | G7: Builds deployable SP transport and customer services.
A8: 4. MPLS Transport: LDP & RSVP-TE | B8: Master legacy and still-deployed MPLS transports | C8: Trace labels end-to-end and repair transport/TE failures | D8: 10 | E8: 44 | F8: 4–5 | G8: Builds deployable SP transport and customer services.
A9: 5. Segment Routing MPLS & SR-TE | B9: Build modern SR-MPLS transport and traffic engineering | C9: Engineer SIDs, policies, TI-LFA and PCE-driven paths | D9: 13 | E9: 58 | F9: 5–6 | G9: Builds deployable SP transport and customer services.
A10: 6. L3VPN & Inter-AS | B10: Deliver resilient IPv4/IPv6 MPLS L3VPN services | C10: Trace VPN routes/labels and solve leaking, PE-CE and Inter-AS faults | D10: 15 | E10: 66 | F10: 5–6 | G10: Builds deployable SP transport and customer services.
A11: 7. L2VPN, EVPN & Multihoming | B11: Deliver VPWS/VPLS/EVPN services over MPLS | C11: Explain EVPN route types, DF, aliasing, mass-withdraw and data-plane behavior | D11: 16 | E11: 72 | F11: 6–7 | G11: Builds deployable SP transport and customer services.
A12: 8. Multicast & mVPN | B12: Operate provider and VPN multicast services | C12: Trace trees, signaling and RPF across core and VPN domains | D12: 11 | E12: 48 | F12: 4–5 | G12: Builds deployable SP transport and customer services.
A13: 9. Access, Metro & Subscriber Edge | B13: Understand realistic SP access and subscriber service handoff | C13: Operate Ethernet access, BNG concepts, DHCP/PPPoE and service demarcation | D13: 7 | E13: 30 | F13: 3–4 | G13: Builds deployable SP transport and customer services.
A14: 10. QoS & Traffic Engineering | B14: Engineer measurable service differentiation | C14: Classify, mark, police, shape, queue and verify under congestion | D14: 8 | E14: 36 | F14: 3–4 | G14: Builds deployable SP transport and customer services.
A15: 11. High Availability & Fast Convergence | B15: Minimize outage across link, node and control-plane failures | C15: Measure failure impact and convergence with BFD, FRR, NSR and GR | D15: 8 | E15: 36 | F15: 3–4 | G15: Builds deployable SP transport and customer services.
A16: 12. Security & Infrastructure Protection | B16: Harden routing, management and data planes | C16: Apply protections without breaking operations and prove attack/failure behavior | D16: 8 | E16: 36 | F16: 3–4 | G16: Builds deployable SP transport and customer services.
... A19: 15. Design, Migration & Expert Integration | B19: Integrate technologies under constraints and timed pressure | C19: Complete mixed-fault scenarios and defend design/change decisions | D19: 12 | E19: 72 | F19: 6–8 | G19: Builds the operating discipline expected from a senior SP engineer.

Sheet Lab Checklist
A1: Lab Checklist
A2: Editable columns: Status, Confidence, Evidence Link/Folder, Completed Date, Notes/Gap | B2: Editable columns: Status, Confidence, Evidence Link/Folder, Completed Date, Notes/Gap | C2: Editable columns: Status, Confidence, Evidence Link/Folder, Completed Date, Notes/Gap | D2: Editable columns: Status, Confidence, Evidence Link/Folder, Completed Date, Notes/Gap | E2: Editable columns: Status, Confidence, Evidence Link/Folder, Completed Date, Notes/Gap | F2: Editable columns: Status, Confidence, Evidence Link/Folder, Completed Date, Notes/Gap | G2: Editable columns: Status, Confidence, Evidence Link/Folder, Completed Date, Notes/Gap | H2: Editable columns: Status, Confidence, Evidence Link/Folder, Completed Date, Notes/Gap
A4: Lab ID | B4: Phase # | C4: Phase / Domain | D4: Lab / Scenario | E4: Mastery Outcome | F4: Suggested Topology | G4: Est. Hours | H4: Difficulty | I4: Priority | J4: Dependency | K4: Status | L4: Confidence (0–5) | M4: Evidence Link/Folder | N4: Completed Date | O4: Required Evidence | P4: Notes/Gap | Q4: Track
A5: LAB-001 | B5: 1 | C5: IOS XR & SP Foundations | D5: IOS XR CLI hierarchy and configuration commits | E5: Configure, explain, verify, break, and restore ios xr cli hierarchy and configuration commits on IOS XR. | F5: 2–3 XR nodes | G5: 2 | H5: Foundation | I5: Core | K5: Not Started | L5: 0 | O5: Configs; control-plane output; forwarding/traffic proof; fault + root cause; pre/post/rollback | Q5: Phase 1
A6: LAB-002 | B6: 1 | C6: IOS XR & SP Foundations | D6: Commit confirmed, rollback and configuration replace | E6: Configure, explain, verify, break, and restore commit confirmed, rollback and configuration replace on IOS XR. | F6: 2–3 XR nodes | G6: 2 | H6: Foundation | I6: Recommended | J6: LAB-001 | K6: Not Started | L6: 0 | O6: Configs; control-plane output; forwarding/traffic proof; fault + root cause; pre/post/rollback | Q6: Phase 1
A7: LAB-003 | B7: 1 | C7: IOS XR & SP Foundations | D7: Interface addressing, MTU and link-state validation | E7: Configure, explain, verify, break, and restore interface addressing, mtu and link-state validation on IOS XR. | F7: 2–3 XR nodes | G7: 2 | H7: Foundation | I7: Recommended | J7: LAB-002 | K7: Not Started | L7: 0 | O7: Configs; control-plane output; forwarding/traffic proof; fault + root cause; pre/post/rollback | Q7: Phase 1
A8: LAB-004 | B8: 1 | C8: IOS XR & SP Foundations | D8: Bundle-Ether with LACP and minimum-active links | E8: Configure, explain, verify, break, and restore bundle-ether with lacp and minimum-active links on IOS XR. | F8: 2–3 XR nodes | G8: 3 | H8: Intermediate | I8: Core | J8: LAB-003 | K8: Not Started | L8: 0 | O8: Configs; control-plane output; forwarding/traffic proof; fault + root cause; pre/post/rollback | Q8: Phase 1
A9: LAB-005 | B9: 1 | C9: IOS XR & SP Foundations | D9: VRF, RIB, CEF and recursive resolution | E9: Configure, explain, verify, break, and restore vrf, rib, cef and recursive resolution on IOS XR. | F9: 2–3 XR nodes | G9: 3 | H9: Intermediate | I9: Recommended | J9: LAB-004 | K9: Not Started | L9: 0 | O9: Configs; control-plane output; forwarding/traffic proof; fault + root cause; pre/post/rollback | Q9: Phase 1
A10: LAB-006 | B10: 1 | C10: IOS XR & SP Foundations | D10: Route-policy language fundamentals | E10: Configure, explain, verify, break, and restore route-policy language fundamentals on IOS XR. | F10: 2–3 XR nodes | G10: 3 | H10: Intermediate | I10: Recommended | J10: LAB-005 | K10: Not Started | L10: 0 | O10: Configs; control-plane output; forwarding/traffic proof; fault + root cause; pre/post/rollback | Q10: Phase 1
A11: LAB-007 | B11: 1 | C11: IOS XR & SP Foundations | D11: Management VRF, SSH, AAA and file operations | E11: Configure, explain, verify, break, and restore management vrf, ssh, aaa and file operations on IOS XR. | F11: 2–3 XR nodes | G11: 3 | H11: Intermediate | I11: Core | J11: LAB-006 | K11: Not Started | L11: 0 | O11: Configs; control-plane output; forwarding/traffic proof; fault + root cause; pre/post/rollback | Q11: Phase 1
A12: LAB-008 | B12: 2 | C12: Dual-Stack IGP Engineering | D12: IS-IS L2 single-area dual stack | E12: Configure, explain, verify, break, and restore is-is l2 single-area dual stack on IOS XR. | F12: 4–6 XR nodes | G12: 2 | H12: Foundation | I12: Core | K12: Not Started | L12: 0 | O12: Configs; control-plane output; forwarding/traffic proof; fault + root cause; pre/post/rollback | Q12: Phase 2
A13: LAB-009 | B13: 2 | C13: Dual-Stack IGP Engineering | D13: IS-IS L1/L2 hierarchy and attached-bit behavior | E13: Configure, explain, verify, break, and restore is-is l1/l2 hierarchy and attached-bit behavior on IOS XR. | F13: 4–6 XR nodes | G13: 2 | H13: Foundation | I13: Recommended | J13: LAB-008 | K13: Not Started | L13: 0 | O13: Configs; control-plane output; forwarding/traffic proof; fault + root cause; pre/post/rollback | Q13: Phase 2
A14: LAB-010 | B14: 2 | C14: Dual-Stack IGP Engineering | D14: IS-IS DIS election, pseudonode and LAN tuning | E14: Configure, explain, verify, break, and restore is-is dis election, pseudonode and lan tuning on IOS XR. | F14: 4–6 XR nodes | G14: 2 | H14: Foundation | I14: Recommended | J14: LAB-009 | K14: Not Started | L14: 0 | O14: Configs; control-plane output; forwarding/traffic proof; fault + root cause; pre/post/rollback | Q14: Phase 2
A15: LAB-011 | B15: 2 | C15: Dual-Stack IGP Engineering | D15: IS-IS wide metrics and overload bit | E15: Configure, explain, verify, break, and restore is-is wide metrics and overload bit on IOS XR. | F15: 4–6 XR nodes | G15: 3 | H15: Intermediate | I15: Core | J15: LAB-010 | K15: Not Started | L15: 0 | O15: Configs; control-plane output; forwarding/traffic proof; fault + root cause; pre/post/rollback | Q15: Phase 2
A16: LAB-012 | B16: 2 | C16: Dual-Stack IGP Engineering | D16: IS-IS route leaking and summarization | E16: Configure, explain, verify, break, and restore is-is route leaking and summarization on IOS XR. | F16: 4–6 XR nodes | G16: 3 | H16: Intermediate | I16: Recommended | J16: LAB-011 | K16: Not Started | L16: 0 | O16: Configs; control-plane output; forwarding/traffic proof; fault + root cause; pre/post/rollback | Q16: Phase 2
A17: LAB-013 | B17: 2 | C17: Dual-Stack IGP Engineering | D17: IS-IS authentication and adjacency faults | E17: Configure, explain, verify, break, and restore is-is authentication and adjacency faults on IOS XR. | F17: 4–6 XR nodes | G17: 3 | H17: Intermediate | I17: Recommended | J17: LAB-012 | K17: Not Started | L17: 0 | O17: Configs; control-plane output; forwarding/traffic proof; fault + root cause; pre/post/rollback | Q17: Phase 2
A18: LAB-014 | B18: 2 | C18: Dual-Stack IGP Engineering | D18: OSPFv2 multi-area and ABR behavior | E18: Configure, explain, verify, break, and restore ospfv2 multi-area and abr behavior on IOS XR. | F18: 4–6 XR nodes | G18: 3 | H18: Intermediate | I18: Core | J18: LAB-013 | K18: Not Started | L18: 0 | O18: Configs; control-plane output; forwarding/traffic proof; fault + root cause; pre/post/rollback | Q18: Phase 2
A19: LAB-015 | B19: 2 | C19: Dual-Stack IGP Engineering | D19: OSPFv3 dual-stack address families | E19: Configure, explain, verify, break, and restore ospfv3 dual-stack address families on IOS XR. | F19: 4–6 XR nodes | G19: 3 | H19: Intermediate | I19: Recommended | J19: LAB-014 | K19: Not Started | L19: 0 | O19: Configs; control-plane output; forwarding/traffic proof; fault + root cause; pre/post/rollback | Q19: Phase 2
A20: LAB-016 | B20: 2 | C20: Dual-Stack IGP Engineering | D20: OSPF network types and DR/BDR behavior | E20: Configure, explain, verify, break, and restore ospf network types and dr/bdr behavior on IOS XR. | F20: 4–6 XR nodes | G20: 3 | H20: Intermediate | I20: Recommended | J20: LAB-015 | K20: Not Started | L20: 0 | O20: Configs; control-plane output; forwarding/traffic proof; fault + root cause; pre/post/rollback | Q20: Phase 2
A21: LAB-017 | B21: 2 | C21: Dual-Stack IGP Engineering | D21: OSPF summarization, filtering and default origination | E21: Configure, explain, verify, break, and restore ospf summarization, filtering and default origination on IOS XR. | F21: 4–6 XR nodes | G21: 3 | H21: Intermediate | I21: Core | J21: LAB-016 | K21: Not Started | L21: 0 | O21: Configs; control-plane output; forwarding/traffic proof; fault + root cause; pre/post/rollback | Q21: Phase 2
A22: LAB-018 | B22: 2 | C22: Dual-Stack IGP Engineering | D22: IGP metric engineering and ECMP | E22: Configure, explain, verify, break, and restore igp metric engineering and ecmp on IOS XR. | F22: 4–6 XR nodes | G22: 3 | H22: Intermediate | I22: Recommended | J22: LAB-017 | K22: Not Started | L22: 0 | O22: Configs; control-plane output; forwarding/traffic proof; fault + root cause; pre/post/rollback | Q22: Phase 2
A23: LAB-019 | B23: 2 | C23: Dual-Stack IGP Engineering | D23: IGP microloop and convergence observation | E23: Configure, explain, verify, break, and restore igp microloop and convergence observation on IOS XR. | F23: 4–6 XR nodes | G23: 3 | H23: Intermediate | I23: Recommended | J23: LAB-018 | K23: Not Started | L23: 0 | O23: Configs; control-plane output; forwarding/traffic proof; fault + root cause; pre/post/rollback | Q23: Phase 2
A24: LAB-020 | B24: 3 | C24: BGP at Service-Provider Scale | D24: eBGP IPv4/IPv6 baseline and multihop | E24: Configure, explain, verify, break, and restore ebgp ipv4/ipv6 baseline and multihop on IOS XR. | F24: 4–6 XR nodes | G24: 4 | H24: Advanced | I24: Core | K24: Not Started | L24: 0 | O24: Configs; control-plane output; forwarding/traffic proof; fault + root cause; pre/post/rollback | Q24: Phase 3
A25: LAB-021 | B25: 3 | C25: BGP at Service-Provider Scale | D25: BGP best-path deep dive and deterministic MED | E25: Configure, explain, verify, break, and restore bgp best-path deep dive and deterministic med on IOS XR. | F25: 4–6 XR nodes | G25: 4 | H25: Advanced | I25: Core | J25: LAB-020 | K25: Not Started | L25: 0 | O25: Configs; control-plane output; forwarding/traffic proof; fault + root cause; pre/post/rollback | Q25: Phase 3
A26: LAB-022 | B26: 3 | C26: BGP at Service-Provider Scale | D26: IOS XR route-policy matching and attribute changes | E26: Configure, explain, verify, break, and restore ios xr route-policy matching and attribute changes on IOS XR. | F26: 4–6 XR nodes | G26: 4 | H26: Advanced | I26: Core | J26: LAB-021 | K26: Not Started | L26: 0 | O26: Configs; control-plane output; forwarding/traffic proof; fault + root cause; pre/post/rollback | Q26: Phase 3
A27: LAB-023 | B27: 3 | C27: BGP at Service-Provider Scale | D27: Prefix-set, AS-path-set and community-set design | E27: Configure, explain, verify, break, and restore prefix-set, as-path-set and community-set design on IOS XR. | F27: 4–6 XR nodes | G27: 6 | H27: Expert | I27: Core | J27: LAB-022 | K27: Not Started | L27: 0 | O27: Configs; control-plane output; forwarding/traffic proof; fault + root cause; pre/post/rollback | Q27: Phase 3
A28: LAB-024 | B28: 3 | C28: BGP at Service-Provider Scale | D28: BGP route reflector baseline and cluster behavior | E28: Configure, explain, verify, break, and restore bgp route reflector baseline and cluster behavior on IOS XR. | F28: 4–6 XR nodes | G28: 4 | H28: Advanced | I28: Core | J28: LAB-023 | K28: Not Started | L28: 0 | O28: Configs; control-plane output; forwarding/traffic proof; fault + root cause; pre/post/rollback | Q28: Phase 3
A29: LAB-025 | B29: 3 | C29: BGP at Service-Provider Scale | D29: Hierarchical route reflection and path hiding | E29: Configure, explain, verify, break, and restore hierarchical route reflection and path hiding on IOS XR. | F29: 4–6 XR nodes | G29: 4 | H29: Advanced | I29: Core | J29: LAB-024 | K29: Not Started | L29: 0 | O29: Configs; control-plane output; forwarding/traffic proof; fault + root cause; pre/post/rollback | Q29: Phase 3
A30: LAB-026 | B30: 3 | C30: BGP at Service-Provider Scale | D30: Add-Path and optimal route reflection concepts | E30: Configure, explain, verify, break, and restore add-path and optimal route reflection concepts on IOS XR. | F30: 4–6 XR nodes | G30: 4 | H30: Advanced | I30: Core | J30: LAB-025 | K30: Not Started | L30: 0 | O30: Configs; control-plane output; forwarding/traffic proof; fault + root cause; pre/post/rollback | Q30: Phase 3
A31: LAB-027 | B31: 3 | C31: BGP at Service-Provider Scale | D31: BGP multipath and unequal policy outcomes | E31: Configure, explain, verify, break, and restore bgp multipath and unequal policy outcomes on IOS XR. | F31: 4–6 XR nodes | G31: 6 | H31: Expert | I31: Core | J31: LAB-026 | K31: Not Started | L31: 0 | O31: Configs; control-plane output; forwarding/traffic proof; fault + root cause; pre/post/rollback | Q31: Phase 3
A32: LAB-028 | B32: 3 | C32: BGP at Service-Provider Scale | D32: BGP aggregation, suppression and conditional advertisement | E32: Configure, explain, verify, break, and restore bgp aggregation, suppression and conditional advertisement on IOS XR. | F32: 4–6 XR nodes | G32: 4 | H32: Advanced | I32: Core | J32: LAB-027 | K32: Not Started | L32: 0 | O32: Configs; control-plane output; forwarding/traffic proof; fault + root cause; pre/post/rollback | Q32: Phase 3
A33: LAB-029 | B33: 3 | C33: BGP at Service-Provider Scale | D33: BGP local-AS, allowas-in and AS override | E33: Configure, explain, verify, break, and restore bgp local-as, allowas-in and as override on IOS XR. | F33: 4–6 XR nodes | G33: 4 | H33: Advanced | I33: Core | J33: LAB-028 | K33: Not Started | L33: 0 | O33: Configs; control-plane output; forwarding/traffic proof; fault + root cause; pre/post/rollback | Q33: Phase 3
A34: LAB-030 | B34: 3 | C34: BGP at Service-Provider Scale | D34: BGP graceful shutdown and maintenance policy | E34: Configure, explain, verify, break, and restore bgp graceful shutdown and maintenance policy on IOS XR. | F34: 4–6 XR nodes | G34: 4 | H34: Advanced | I34: Core | J34: LAB-029 | K34: Not Started | L34: 0 | O34: Configs; control-plane output; forwarding/traffic proof; fault + root cause; pre/post/rollback | Q34: Phase 3
A35: LAB-031 | B35: 3 | C35: BGP at Service-Provider Scale | D35: BGP maximum-prefix and session protection | E35: Configure, explain, verify, break, and restore bgp maximum-prefix and session protection on IOS XR. | F35: 4–6 XR nodes | G35: 6 | H35: Expert | I35: Core | J35: LAB-030 | K35: Not Started | L35: 0 | O35: Configs; control-plane output; forwarding/traffic proof; fault + root cause; pre/post/rollback | Q35: Phase 3
A36: LAB-032 | B36: 3 | C36: BGP at Service-Provider Scale | D36: BGP labeled-unicast transport | E36: Configure, explain, verify, break, and restore bgp labeled-unicast transport on IOS XR. | F36: 4–6 XR nodes | G36: 4 | H36: Advanced | I36: Core | J36: LAB-031 | K36: Not Started | L36: 0 | O36: Configs; control-plane output; forwarding/traffic proof; fault + root cause; pre/post/rollback | Q36: Phase 3
A37: LAB-033 | B37: 3 | C37: BGP at Service-Provider Scale | D37: BGP convergence, PIC edge/core and next-hop tracking | E37: Configure, explain, verify, break, and restore bgp convergence, pic edge/core and next-hop tracking on IOS XR. | F37: 4–6 XR nodes | G37: 4 | H37: Advanced | I37: Core | J37: LAB-032 | K37: Not Started | L37: 0 | O37: Configs; control-plane output; forwarding/traffic proof; fault + root cause; pre/post/rollback | Q37: Phase 3
A38: LAB-034 | B38: 4 | C38: MPLS Transport: LDP & RSVP-TE | D38: LDP discovery, sessions and label bindings | E38: Configure, explain, verify, break, and restore ldp discovery, sessions and label bindings on IOS XR. | F38: 4–6 XR nodes | G38: 4 | H38: Advanced | I38: Core | K38: Not Started | L38: 0 | O38: Configs; control-plane output; forwarding/traffic proof; fault + root cause; pre/post/rollback | Q38: Phase 4
A39: LAB-035 | B39: 4 | C39: MPLS Transport: LDP & RSVP-TE | D39: LDP router-id and transport-address failure | E39: Configure, explain, verify, break, and restore ldp router-id and transport-address failure on IOS XR. | F39: 4–6 XR nodes | G39: 4 | H39: Advanced | I39: Recommended | J39: LAB-034 | K39: Not Started | L39: 0 | O39: Configs; control-plane output; forwarding/traffic proof; fault + root cause; pre/post/rollback | Q39: Phase 4
A40: LAB-036 | B40: 4 | C40: MPLS Transport: LDP & RSVP-TE | D40: LDP-IGP synchronization | E40: Configure, explain, verify, break, and restore ldp-igp synchronization on IOS XR. | F40: 4–6 XR nodes | G40: 4 | H40: Advanced | I40: Recommended | J40: LAB-035 | K40: Not Started | L40: 0 | O40: Configs; control-plane output; forwarding/traffic proof; fault + root cause; pre/post/rollback | Q40: Phase 4
A41: LAB-037 | B41: 4 | C41: MPLS Transport: LDP & RSVP-TE | D41: Targeted LDP session and pseudowire transport | E41: Configure, explain, verify, break, and restore targeted ldp session and pseudowire transport on IOS XR. | F41: 4–6 XR nodes | G41: 6 | H41: Expert | I41: Core | J41: LAB-036 | K41: Not Started | L41: 0 | O41: Configs; control-plane output; forwarding/traffic proof; fault + root cause; pre/post/rollback | Q41: Phase 4
...

Sheet Capstones
A1: Capstones & Timed Milestones
A2: Attempt only after the prerequisite phases meet their exit gates | B2: Attempt only after the prerequisite phases meet their exit gates | C2: Attempt only after the prerequisite phases meet their exit gates | D2: Attempt only after the prerequisite phases meet their exit gates | E2: Attempt only after the prerequisite phases meet their exit gates | F2: Attempt only after the prerequisite phases meet their exit gates | G2: Attempt only after the prerequisite phases meet their exit gates | H2: Attempt only after the prerequisite phases meet their exit gates
A4: ID | B4: Name | C4: Prerequisite Phases | D4: Scenario | E4: Nodes | F4: Timebox | G4: Required Evidence | H4: Status | I4: Confidence | J4: Notes / Gap
A5: CAP-01 | B5: Core Bring-up | C5: 1–3 | D5: Build dual-stack IS-IS + RR-based BGP core from blank | E5: 6 | F5: Untimed | G5: Core reachability, policy, evidence pack | H5: Not Started | I5: 0
A6: CAP-02 | B6: MPLS Transport | C6: 2–5 | D6: Run LDP, RSVP-TE and SR-MPLS transports; compare forwarding and failure behavior | E6: 8 | F6: Untimed | G6: Label trace, TE path, failure comparison | H6: Not Started | I6: 0
A7: CAP-03 | B7: L3VPN Provider | C7: 3–6 | D7: Deploy dual-stack L3VPN with diverse PE-CE and selective leaking | E7: 8 | F7: 6 hours | G7: Service matrix, route/label trace, rollback | H7: Not Started | I7: 0
A8: CAP-04 | B8: EVPN Metro | C8: 3,5,7,11 | D8: Deploy EVPN E-LAN/VPWS with all-active multihoming and convergence tests | E8: 8 | F8: 6 hours | G8: EVPN route proof, DF/failover timing, OAM | H8: Not Started | I8: 0
A9: CAP-05 | B9: mVPN + QoS | C9: 6,8,10 | D9: Deliver multicast VPN with measurable QoS under congestion | E9: 6 | F9: 5 hours | G9: Tree/RPF proof, loss/queue measurements | H9: Not Started | I9: 0
A10: CAP-06 | B10: Secure Operations | C10: 11–14 | D10: Harden, instrument and automate a brownfield service network | E10: 8 | F10: 6 hours | G10: Change plan, telemetry, compliance and rollback | H10: Not Started | I10: 0
A11: CAP-07 | B11: Mixed Fault Marathon | C11: All | D11: Diagnose 12 seeded faults spanning underlay, transport, VPN, QoS and security | E11: 10 | F11: 8 hours | G11: Hypothesis/evidence log and minimal fixes | H11: Not Started | I11: 0
A12: CAP-08 | B12: Full CCIE-SP Simulation | C12: All | D12: Plan/design, deploy, operate and optimize a complex dual-stack SP network | E12: 12 | F12: 8 hours | G12: Score sheet, evidence package and gap backlog | H12: Not Started | I12: 0

Sheet Sources
A1: Sources & Scope Notes
A2: Official Cisco references used to anchor the current certification scope; roadmap intentionally extends beyond the exam | B2: Official Cisco references used to anchor the current certification scope; roadmap intentionally extends beyond the exam | C2: Official Cisco references used to anchor the current certification scope; roadmap intentionally extends beyond the exam | D2: Official Cisco references used to anchor the current certification scope; roadmap intentionally extends beyond the exam | E2: Official Cisco references used to anchor the current certification scope; roadmap intentionally extends beyond the exam | F2: Official Cisco references used to anchor the current certification scope; roadmap intentionally extends beyond the exam | G2: Official Cisco references used to anchor the current certification scope; roadmap intentionally extends beyond the exam | H2: Official Cisco references used to anchor the current certification scope; roadmap intentionally extends beyond the exam
A4: Source | B4: URL | C4: Used For | D4: Scope Note
A5: CCIE Service Provider v5.1 Practical Exam Topics | B5: https://learningnetwork.cisco.com/s/ccie-service-provider-exam-topics | C5: Current practical-domain alignment | D5: Core routing; architectures/services; access; convergence; security/assurance/automation
A6: CCIE Service Provider exams and training | B6: https://www.cisco.com/site/us/en/learn/training-certifications/certifications/service-provider/ccie-service-provider/exams-and-training.html | C6: Current exam intent and lifecycle | D6: Plan, design, implement, operate, and optimize dual-stack SP networks
A7: CCIE Service Provider v5.1 equipment/software list | B7: https://learningnetwork.cisco.com/s/article/ccie-service-provider-v5-0-equipment-and-software-list | C7: Platform awareness | D7: Exact feature support depends on the lab image/release
A8: Cisco IOS XR configuration guides | B8: https://www.cisco.com/c/en/us/support/ios-nx-os-software/ios-xr-software/products-installation-and-configuration-guides-list.html | C8: Implementation reference | D8: Use release-matched guides while executing each lab
